Workbook

Sheet Wand Mapping
A1: Wand | B1: Abjuration | C1: Conjuration | D1: Divination | E1: Transmutation | F1: Invocation | G1: Enchantment | H1: Necromancy | I1: Illusion | J1: Wild Magic | K1: Wand ID
C2: Power Word Sleep | F2: Black Blade of Disaster | H2: False Life | K2: wand_ai_000
C3: Empower Familiar | H3: Cause Moderate Wounds | K3: wand_ai_010
C4: Conjure Animals | F4: Blade Barrier | G4: Turning Weapon | H4: Death Spell | I4: Wraith Form | K4: wand_ai_020
B5: Antimagic Shell | C5: Find Familiar | H5: Reanimate | K5: wand_ai_030
B6: Pierce Shield | C6: Elemental Summoning | D6: Executioner's Eyes | H6: Soul Eater | K6: wand_ai_040
B7: Protection from Time Stop | C7: Maze | E7: Stone Skin | H7: Cause Medium Wounds | K7: wand_ai_050
B8: Spellstrike | C8: Monster Summoning 3 | F8: Delayed Blast Fireball | G8: Chaos | H8: Cause Critical Wounds | K8: wand_ai_060
B9: Armor of Faith | C9: Chant | D9: Clairvoyance | G9: Righteous Wrath of the Faithful | H9: Mass Heal | J9: Chaos Shield* | K9: wand_ai_070
B10: Protection from Electricity | C10: Bless | F10: Stinking Cloud | G10: Greater Malison | I10: Warrior Simulacrum | K10: wand_ai_080
C11: Fire Seeds | E11: Fire Curse | F11: Fire Shield (Red) | H11: Vampiric Feast | K11: wand_ai_090
C12: Conjure Fire Elemental | D12: Infravision | E12: Fire Earth Transformation | F12: Fireball | G12: Friends | K12: wand_ai_100
B13: Minor Spell Turning | C13: Ghost Armor | E13: Greater Steel Wind Strike | H13: Slay Living | K13: wand_ai_110
B14: Recitation | C14: Power Word, Kill | D14: Detect Illusion | E14: Sphere of Chaos | F14: Incendiary Cloud | G14: Charm Person | H14: Raise Dead | I14: Camouflage | K14: wand_ai_120
B15: Protection from Evil | C15: Melf's Acid Arrow | E15: Animal Growth | F15: Fire Shield (Blue) | H15: Neutralize Poison | K15: wand_ai_130
C16: Limited Wish | E16: Pebbles to Boulders | F16: Chain Contingency | H16: Mass Raise Dead | K16: wand_ai_140
B17: Exaltation | C17: Glitterdust | E17: Spellshaping: Fireball | F17: Mist of Eldath | H17: Resurrection | K17: wand_ai_150
C18: Monster Summoning 1 | E18: Otiluke's Resilient Sphere | F18: Acid Storm | H18: Sacrificial Explosion | K18: wand_ai_160
B19: Breach | C19: Symbol, Death | D19: Know Alignment | E19: Steal Spells | F19: Isaac's Greater Missile Storm | G19: Luck | I19: Perfect Invisibility | K19: wand_ai_170
C20: Stygian Ice Storm | E20: Shocking Grasp | F20: Ball Lightning | I20: Mirror Image | K20: wand_ai_180
C21: Writhing Fog | E21: Levitate | F21: Otiluke's Freezing Sphere | H21: Finger of Death | K21: wand_ai_190
C22: Greater Shield of Lathander | E22: Wondrous Recall | F22: Lance of Disruption | H22: Spirit Armor | K22: wand_ai_200
B23: Antiharm Shell | C23: Conjure Earth Elemental | D23: Oracle | E23: Strength of One | F23: Minor Sequencer | H23: Undead Ward | K23: wand_ai_210
B24: Cause Disease | C24: Mestil's Acid Breath | E24: Teleport Step | G24: Emotion: Hope | H24: Vampiric Touch | K24: wand_ai_220
C25: Ethereal Retribution | E25: Strength | F25: Chain Lightning | K25: wand_ai_230
B26: Protection from Normal Weapons | C26: Wish | D26: Extend Vision | E26: Drown | F26: Alicorn Lance | H26: Cure Serious Wounds | K26: wand_ai_240
B27: Entropy Shield | C27: Spirit Fire | E27: Steel Wind Strike | F27: Draw Upon Holy Might | G27: Emotion: Courage | K27: wand_ai_250
B28: Remove Paralysis | C28: Monster Summoning 7 | E28: Wind Shots | K28: wand_ai_260
B29: Bounce Spell | C29: Power Word: Pull | E29: Mold Touch | G29: Hold Person | H29: Recall Spirit | K29: wand_ai_270
C30: Recall Party | E30: Tenser's Transformation | F30: Energy Blades | H30: Unholy Blight | K30: wand_ai_280
C31: Symbol, Stun | D31: Contact Other Plane | E31: Beast Claw | F31: Bolt of Glory | G31: Disarm | H31: Wail of the Banshee | K31: wand_ai_290
B32: Freedom | C32: Monster Summoning 5 | E32: Rewind Time | F32: Freezing Wave | H32: Necropotence | I32: Phantasmal Dragon | K32: wand_ai_300
B33: Imprisonment | C33: Summon Fiend | E33: Teleport Field | H33: Vampiric Link | K33: wand_ai_310
B34: Protection From Non-Silver Weapons | C34: Sphere of Annihilation | E34: Sphere of Reversed Gravity | F34: Spiritual Wrath | H34: Abi-Dalzim's Horrid Wilting | K34: wand_ai_320
B35: Mantle | C35: Slime Drop | E35: Knock | F35: Whirlwind | H35: Cure Light Wounds | K35: wand_ai_330
B36: Absord Spell | C36: Wyvern Call | E36: Fire Elemental Transformation | F36: Heavenly Inferno | H36: Terror | J36: Disruptive Surge | K36: wand_ai_340
B37: Mind Blank | C37: Curse | E37: Skip Time | F37: Sunfire | H37: Mass Cure Light Wounds | K37: wand_ai_350
B38: Repulse | C38: Summon Kobold | E38: Silence 15' Radius | F38: Rampant Lightning | K38: wand_ai_360
B39: Forcecage | C39: Storm of Vengeance | E39: Shillelagh | F39: Smashing Wave | H39: Aid | K39: wand_ai_370
B40: Negative Plane Protection | C40: Elysium's Tears | E40: Burning Hands | F40: Bigby's Clenched Fist | H40: Linked Spirit | K40: wand_ai_380
...

Sheet Spells Per School
B1: Wild Magic | C1: Divination | D1: Illusion | E1: Enchantment | F1: Necromancy | G1: Abjuration | H1: Invocation | I1: Transmutation | J1: Conjuration
A2: Count | B2: 4 | C2: 20 | D2: 30 | E2: 47 | F2: 78 | G2: 82 | H2: 83 | I2: 90 | J2: 96

Sheet Tinker-Suffixes
A1: Base | B1: Wild Magic | C1: Divination | D1: Illusion | E1: Enchantment | F1: Necromancy | G1: Abjuration | H1: Invocation | I1: Transmutation | J1: Conjuration | K1: Suffix | L1: RAND | M1: OVERRIDE | N1: Result
A2: ='Wand Mapping'!K2 -> wand_ai_000 | B2: =IF(NOT(ISBLANK('Wand Mapping'!$J2)), "WM") -> FALSE | C2: =IF(NOT(ISBLANK('Wand Mapping'!$D2)), "DI") -> FALSE | D2: =IF(NOT(ISBLANK('Wand Mapping'!$I2)), "IL") -> FALSE | E2: =IF(NOT(ISBLANK('Wand Mapping'!$G2)), "EN") -> FALSE | F2: =IF(NOT(ISBLANK('Wand Mapping'!$H2)), "NE") -> NE | G2: =IF(NOT(ISBLANK('Wand Mapping'!$B2)), "AB") -> FALSE | H2: =IF(NOT(ISBLANK('Wand Mapping'!$F2)), "EV") -> EV | I2: =IF(NOT(ISBLANK('Wand Mapping'!$E2)), "TR") -> FALSE | J2: =IF(NOT(ISBLANK('Wand Mapping'!$C2)), "CO") -> CO | K2: =IF(B2=FALSE, IF(C2=FALSE, IF(D2=FALSE, IF(E2=FALSE, "RAND", E2), D2), C2), B2) -> RAND | L2: =IF(K2="RAND", OFFSET(F2, 0, MOD(RAND(), 3)), K2) -> NE | M2: EV | N2: =_xlfn.CONCAT(A2, "-", M2, ".BAM") -> wand_ai_000-EV.BAM
A3: ='Wand Mapping'!K3 -> wand_ai_010 | B3: =IF(NOT(ISBLANK('Wand Mapping'!$J3)), "WM") -> FALSE | C3: =IF(NOT(ISBLANK('Wand Mapping'!$D3)), "DI") -> FALSE | D3: =IF(NOT(ISBLANK('Wand Mapping'!$I3)), "IL") -> FALSE | E3: =IF(NOT(ISBLANK('Wand Mapping'!$G3)), "EN") -> FALSE | F3: =IF(NOT(ISBLANK('Wand Mapping'!$H3)), "NE") -> NE | G3: =IF(NOT(ISBLANK('Wand Mapping'!$B3)), "AB") -> FALSE | H3: =IF(NOT(ISBLANK('Wand Mapping'!$F3)), "EV") -> FALSE | I3: =IF(NOT(ISBLANK('Wand Mapping'!$E3)), "TR") -> FALSE | J3: =IF(NOT(ISBLANK('Wand Mapping'!$C3)), "CO") -> CO | K3: =IF(B3=FALSE, IF(C3=FALSE, IF(D3=FALSE, IF(E3=FALSE, "RAND", E3), D3), C3), B3) -> RAND | L3: =IF(K3="RAND", OFFSET(F3, 0, MOD(RAND(), 3)), K3) -> NE | M3: =IF(L3=FALSE, ,L3) -> NE | N3: =_xlfn.CONCAT(A3, "-", M3, ".BAM") -> wand_ai_010-NE.BAM
A4: ='Wand Mapping'!K4 -> wand_ai_020 | B4: =IF(NOT(ISBLANK('Wand Mapping'!$J4)), "WM") -> FALSE | C4: =IF(NOT(ISBLANK('Wand Mapping'!$D4)), "DI") -> FALSE | D4: =IF(NOT(ISBLANK('Wand Mapping'!$I4)), "IL") -> IL | E4: =IF(NOT(ISBLANK('Wand Mapping'!$G4)), "EN") -> EN | F4: =IF(NOT(ISBLANK('Wand Mapping'!$H4)), "NE") -> NE | G4: =IF(NOT(ISBLANK('Wand Mapping'!$B4)), "AB") -> FALSE | H4: =IF(NOT(ISBLANK('Wand Mapping'!$F4)), "EV") -> EV | I4: =IF(NOT(ISBLANK('Wand Mapping'!$E4)), "TR") -> FALSE | J4: =IF(NOT(ISBLANK('Wand Mapping'!$C4)), "CO") -> CO | K4: =IF(B4=FALSE, IF(C4=FALSE, IF(D4=FALSE, IF(E4=FALSE, "RAND", E4), D4), C4), B4) -> IL | L4: =IF(K4="RAND", OFFSET(F4, 0, MOD(RAND(), 3)), K4) -> IL | M4: =IF(L4=FALSE, ,L4) -> IL | N4: =_xlfn.CONCAT(A4, "-", M4, ".BAM") -> wand_ai_020-IL.BAM
A5: ='Wand Mapping'!K5 -> wand_ai_030 | B5: =IF(NOT(ISBLANK('Wand Mapping'!$J5)), "WM") -> FALSE | C5: =IF(NOT(ISBLANK('Wand Mapping'!$D5)), "DI") -> FALSE | D5: =IF(NOT(ISBLANK('Wand Mapping'!$I5)), "IL") -> FALSE | E5: =IF(NOT(ISBLANK('Wand Mapping'!$G5)), "EN") -> FALSE | F5: =IF(NOT(ISBLANK('Wand Mapping'!$H5)), "NE") -> NE | G5: =IF(NOT(ISBLANK('Wand Mapping'!$B5)), "AB") -> AB | H5: =IF(NOT(ISBLANK('Wand Mapping'!$F5)), "EV") -> FALSE | I5: =IF(NOT(ISBLANK('Wand Mapping'!$E5)), "TR") -> FALSE | J5: =IF(NOT(ISBLANK('Wand Mapping'!$C5)), "CO") -> CO | K5: =IF(B5=FALSE, IF(C5=FALSE, IF(D5=FALSE, IF(E5=FALSE, "RAND", E5), D5), C5), B5) -> RAND | L5: =IF(K5="RAND", OFFSET(F5, 0, MOD(RAND(), 3)), K5) -> NE | M5: CO | N5: =_xlfn.CONCAT(A5, "-", M5, ".BAM") -> wand_ai_030-CO.BAM
A6: ='Wand Mapping'!K6 -> wand_ai_040 | B6: =IF(NOT(ISBLANK('Wand Mapping'!$J6)), "WM") -> FALSE | C6: =IF(NOT(ISBLANK('Wand Mapping'!$D6)), "DI") -> DI | D6: =IF(NOT(ISBLANK('Wand Mapping'!$I6)), "IL") -> FALSE | E6: =IF(NOT(ISBLANK('Wand Mapping'!$G6)), "EN") -> FALSE | F6: =IF(NOT(ISBLANK('Wand Mapping'!$H6)), "NE") -> NE | G6: =IF(NOT(ISBLANK('Wand Mapping'!$B6)), "AB") -> AB | H6: =IF(NOT(ISBLANK('Wand Mapping'!$F6)), "EV") -> FALSE | I6: =IF(NOT(ISBLANK('Wand Mapping'!$E6)), "TR") -> FALSE | J6: =IF(NOT(ISBLANK('Wand Mapping'!$C6)), "CO") -> CO | K6: =IF(B6=FALSE, IF(C6=FALSE, IF(D6=FALSE, IF(E6=FALSE, "RAND", E6), D6), C6), B6) -> DI | L6: =IF(K6="RAND", OFFSET(F6, 0, MOD(RAND(), 3)), K6) -> DI | M6: =IF(L6=FALSE, ,L6) -> DI | N6: =_xlfn.CONCAT(A6, "-", M6, ".BAM") -> wand_ai_040-DI.BAM
A7: ='Wand Mapping'!K7 -> wand_ai_050 | B7: =IF(NOT(ISBLANK('Wand Mapping'!$J7)), "WM") -> FALSE | C7: =IF(NOT(ISBLANK('Wand Mapping'!$D7)), "DI") -> FALSE | D7: =IF(NOT(ISBLANK('Wand Mapping'!$I7)), "IL") -> FALSE | E7: =IF(NOT(ISBLANK('Wand Mapping'!$G7)), "EN") -> FALSE | F7: =IF(NOT(ISBLANK('Wand Mapping'!$H7)), "NE") -> NE | G7: =IF(NOT(ISBLANK('Wand Mapping'!$B7)), "AB") -> AB | H7: =IF(NOT(ISBLANK('Wand Mapping'!$F7)), "EV") -> FALSE | I7: =IF(NOT(ISBLANK('Wand Mapping'!$E7)), "TR") -> TR | J7: =IF(NOT(ISBLANK('Wand Mapping'!$C7)), "CO") -> CO | K7: =IF(B7=FALSE, IF(C7=FALSE, IF(D7=FALSE, IF(E7=FALSE, "RAND", E7), D7), C7), B7) -> RAND | L7: =IF(K7="RAND", OFFSET(F7, 0, MOD(RAND(), 3)), K7) -> NE | M7: TR | N7: =_xlfn.CONCAT(A7, "-", M7, ".BAM") -> wand_ai_050-TR.BAM
A8: ='Wand Mapping'!K8 -> wand_ai_060 | B8: =IF(NOT(ISBLANK('Wand Mapping'!$J8)), "WM") -> FALSE | C8: =IF(NOT(ISBLANK('Wand Mapping'!$D8)), "DI") -> FALSE | D8: =IF(NOT(ISBLANK('Wand Mapping'!$I8)), "IL") -> FALSE | E8: =IF(NOT(ISBLANK('Wand Mapping'!$G8)), "EN") -> EN | F8: =IF(NOT(ISBLANK('Wand Mapping'!$H8)), "NE") -> NE | G8: =IF(NOT(ISBLANK('Wand Mapping'!$B8)), "AB") -> AB | H8: =IF(NOT(ISBLANK('Wand Mapping'!$F8)), "EV") -> EV | I8: =IF(NOT(ISBLANK('Wand Mapping'!$E8)), "TR") -> FALSE | J8: =IF(NOT(ISBLANK('Wand Mapping'!$C8)), "CO") -> CO | K8: =IF(B8=FALSE, IF(C8=FALSE, IF(D8=FALSE, IF(E8=FALSE, "RAND", E8), D8), C8), B8) -> EN | L8: =IF(K8="RAND", OFFSET(F8, 0, MOD(RAND(), 3)), K8) -> EN | M8: =IF(L8=FALSE, ,L8) -> EN | N8: =_xlfn.CONCAT(A8, "-", M8, ".BAM") -> wand_ai_060-EN.BAM
A9: ='Wand Mapping'!K9 -> wand_ai_070 | B9: =IF(NOT(ISBLANK('Wand Mapping'!$J9)), "WM") -> WM | C9: =IF(NOT(ISBLANK('Wand Mapping'!$D9)), "DI") -> DI | D9: =IF(NOT(ISBLANK('Wand Mapping'!$I9)), "IL") -> FALSE | E9: =IF(NOT(ISBLANK('Wand Mapping'!$G9)), "EN") -> EN | F9: =IF(NOT(ISBLANK('Wand Mapping'!$H9)), "NE") -> NE | G9: =IF(NOT(ISBLANK('Wand Mapping'!$B9)), "AB") -> AB | H9: =IF(NOT(ISBLANK('Wand Mapping'!$F9)), "EV") -> FALSE | I9: =IF(NOT(ISBLANK('Wand Mapping'!$E9)), "TR") -> FALSE | J9: =IF(NOT(ISBLANK('Wand Mapping'!$C9)), "CO") -> CO | K9: =IF(B9=FALSE, IF(C9=FALSE, IF(D9=FALSE, IF(E9=FALSE, "RAND", E9), D9), C9), B9) -> WM | L9: =IF(K9="RAND", OFFSET(F9, 0, MOD(RAND(), 3)), K9) -> WM | M9: =IF(L9=FALSE, ,L9) -> WM | N9: =_xlfn.CONCAT(A9, "-", M9, ".BAM") -> wand_ai_070-WM.BAM
A10: ='Wand Mapping'!K10 -> wand_ai_080 | B10: =IF(NOT(ISBLANK('Wand Mapping'!$J10)), "WM") -> FALSE | C10: =IF(NOT(ISBLANK('Wand Mapping'!$D10)), "DI") -> FALSE | D10: =IF(NOT(ISBLANK('Wand Mapping'!$I10)), "IL") -> IL | E10: =IF(NOT(ISBLANK('Wand Mapping'!$G10)), "EN") -> EN | F10: =IF(NOT(ISBLANK('Wand Mapping'!$H10)), "NE") -> FALSE | G10: =IF(NOT(ISBLANK('Wand Mapping'!$B10)), "AB") -> AB | H10: =IF(NOT(ISBLANK('Wand Mapping'!$F10)), "EV") -> EV | I10: =IF(NOT(ISBLANK('Wand Mapping'!$E10)), "TR") -> FALSE | J10: =IF(NOT(ISBLANK('Wand Mapping'!$C10)), "CO") -> CO | K10: =IF(B10=FALSE, IF(C10=FALSE, IF(D10=FALSE, IF(E10=FALSE, "RAND", E10), D10), C10), B10) -> IL | L10: =IF(K10="RAND", OFFSET(F10, 0, MOD(RAND(), 3)), K10) -> IL | M10: =IF(L10=FALSE, ,L10) -> IL | N10: =_xlfn.CONCAT(A10, "-", M10, ".BAM") -> wand_ai_080-IL.BAM
A11: ='Wand Mapping'!K11 -> wand_ai_090 | B11: =IF(NOT(ISBLANK('Wand Mapping'!$J11)), "WM") -> FALSE | C11: =IF(NOT(ISBLANK('Wand Mapping'!$D11)), "DI") -> FALSE | D11: =IF(NOT(ISBLANK('Wand Mapping'!$I11)), "IL") -> FALSE | E11: =IF(NOT(ISBLANK('Wand Mapping'!$G11)), "EN") -> FALSE | F11: =IF(NOT(ISBLANK('Wand Mapping'!$H11)), "NE") -> NE | G11: =IF(NOT(ISBLANK('Wand Mapping'!$B11)), "AB") -> FALSE | H11: =IF(NOT(ISBLANK('Wand Mapping'!$F11)), "EV") -> EV | I11: =IF(NOT(ISBLANK('Wand Mapping'!$E11)), "TR") -> TR | J11: =IF(NOT(ISBLANK('Wand Mapping'!$C11)), "CO") -> CO | K11: =IF(B11=FALSE, IF(C11=FALSE, IF(D11=FALSE, IF(E11=FALSE, "RAND", E11), D11), C11), B11) -> RAND | L11: =IF(K11="RAND", OFFSET(F11, 0, MOD(RAND(), 3)), K11) -> NE | M11: EV | N11: =_xlfn.CONCAT(A11, "-", M11, ".BAM") -> wand_ai_090-EV.BAM
A12: ='Wand Mapping'!K12 -> wand_ai_100 | B12: =IF(NOT(ISBLANK('Wand Mapping'!$J12)), "WM") -> FALSE | C12: =IF(NOT(ISBLANK('Wand Mapping'!$D12)), "DI") -> DI | D12: =IF(NOT(ISBLANK('Wand Mapping'!$I12)), "IL") -> FALSE | E12: =IF(NOT(ISBLANK('Wand Mapping'!$G12)), "EN") -> EN | F12: =IF(NOT(ISBLANK('Wand Mapping'!$H12)), "NE") -> FALSE | G12: =IF(NOT(ISBLANK('Wand Mapping'!$B12)), "AB") -> FALSE | H12: =IF(NOT(ISBLANK('Wand Mapping'!$F12)), "EV") -> EV | I12: =IF(NOT(ISBLANK('Wand Mapping'!$E12)), "TR") -> TR | J12: =IF(NOT(ISBLANK('Wand Mapping'!$C12)), "CO") -> CO | K12: =IF(B12=FALSE, IF(C12=FALSE, IF(D12=FALSE, IF(E12=FALSE, "RAND", E12), D12), C12), B12) -> DI | L12: =IF(K12="RAND", OFFSET(F12, 0, MOD(RAND(), 3)), K12) -> DI | M12: =IF(L12=FALSE, ,L12) -> DI | N12: =_xlfn.CONCAT(A12, "-", M12, ".BAM") -> wand_ai_100-DI.BAM
A13: ='Wand Mapping'!K13 -> wand_ai_110 | B13: =IF(NOT(ISBLANK('Wand Mapping'!$J13)), "WM") -> FALSE | C13: =IF(NOT(ISBLANK('Wand Mapping'!$D13)), "DI") -> FALSE | D13: =IF(NOT(ISBLANK('Wand Mapping'!$I13)), "IL") -> FALSE | E13: =IF(NOT(ISBLANK('Wand Mapping'!$G13)), "EN") -> FALSE | F13: =IF(NOT(ISBLANK('Wand Mapping'!$H13)), "NE") -> NE | G13: =IF(NOT(ISBLANK('Wand Mapping'!$B13)), "AB") -> AB | H13: =IF(NOT(ISBLANK('Wand Mapping'!$F13)), "EV") -> FALSE | I13: =IF(NOT(ISBLANK('Wand Mapping'!$E13)), "TR") -> TR | J13: =IF(NOT(ISBLANK('Wand Mapping'!$C13)), "CO") -> CO | K13: =IF(B13=FALSE, IF(C13=FALSE, IF(D13=FALSE, IF(E13=FALSE, "RAND", E13), D13), C13), B13) -> RAND | L13: =IF(K13="RAND", OFFSET(F13, 0, MOD(RAND(), 3)), K13) -> NE | M13: =IF(L13=FALSE, ,L13) -> NE | N13: =_xlfn.CONCAT(A13, "-", M13, ".BAM") -> wand_ai_110-NE.BAM
A14: ='Wand Mapping'!K14 -> wand_ai_120 | B14: =IF(NOT(ISBLANK('Wand Mapping'!$J14)), "WM") -> FALSE | C14: =IF(NOT(ISBLANK('Wand Mapping'!$D14)), "DI") -> DI | D14: =IF(NOT(ISBLANK('Wand Mapping'!$I14)), "IL") -> IL | E14: =IF(NOT(ISBLANK('Wand Mapping'!$G14)), "EN") -> EN | F14: =IF(NOT(ISBLANK('Wand Mapping'!$H14)), "NE") -> NE | G14: =IF(NOT(ISBLANK('Wand Mapping'!$B14)), "AB") -> AB | H14: =IF(NOT(ISBLANK('Wand Mapping'!$F14)), "EV") -> EV | I14: =IF(NOT(ISBLANK('Wand Mapping'!$E14)), "TR") -> TR | J14: =IF(NOT(ISBLANK('Wand Mapping'!$C14)), "CO") -> CO | K14: =IF(B14=FALSE, IF(C14=FALSE, IF(D14=FALSE, IF(E14=FALSE, "RAND", E14), D14), C14), B14) -> DI | L14: =IF(K14="RAND", OFFSET(F14, 0, MOD(RAND(), 3)), K14) -> DI | M14: =IF(L14=FALSE, ,L14) -> DI | N14: =_xlfn.CONCAT(A14, "-", M14, ".BAM") -> wand_ai_120-DI.BAM
A15: ='Wand Mapping'!K15 -> wand_ai_130 | B15: =IF(NOT(ISBLANK('Wand Mapping'!$J15)), "WM") -> FALSE | C15: =IF(NOT(ISBLANK('Wand Mapping'!$D15)), "DI") -> FALSE | D15: =IF(NOT(ISBLANK('Wand Mapping'!$I15)), "IL") -> FALSE | E15: =IF(NOT(ISBLANK('Wand Mapping'!$G15)), "EN") -> FALSE | F15: =IF(NOT(ISBLANK('Wand Mapping'!$H15)), "NE") -> NE | G15: =IF(NOT(ISBLANK('Wand Mapping'!$B15)), "AB") -> AB | H15: =IF(NOT(ISBLANK('Wand Mapping'!$F15)), "EV") -> EV | I15: =IF(NOT(ISBLANK('Wand Mapping'!$E15)), "TR") -> TR | J15: =IF(NOT(ISBLANK('Wand Mapping'!$C15)), "CO") -> CO | K15: =IF(B15=FALSE, IF(C15=FALSE, IF(D15=FALSE, IF(E15=FALSE, "RAND", E15), D15), C15), B15) -> RAND | L15: =IF(K15="RAND", OFFSET(F15, 0, MOD(RAND(), 3)), K15) -> NE | M15: =IF(L15=FALSE, ,L15) -> NE | N15: =_xlfn.CONCAT(A15, "-", M15, ".BAM") -> wand_ai_130-NE.BAM
A16: ='Wand Mapping'!K16 -> wand_ai_140 | B16: =IF(NOT(ISBLANK('Wand Mapping'!$J16)), "WM") -> FALSE | C16: =IF(NOT(ISBLANK('Wand Mapping'!$D16)), "DI") -> FALSE | D16: =IF(NOT(ISBLANK('Wand Mapping'!$I16)), "IL") -> FALSE | E16: =IF(NOT(ISBLANK('Wand Mapping'!$G16)), "EN") -> FALSE | F16: =IF(NOT(ISBLANK('Wand Mapping'!$H16)), "NE") -> NE | G16: =IF(NOT(ISBLANK('Wand Mapping'!$B16)), "AB") -> FALSE | H16: =IF(NOT(ISBLANK('Wand Mapping'!$F16)), "EV") -> EV | I16: =IF(NOT(ISBLANK('Wand Mapping'!$E16)), "TR") -> TR | J16: =IF(NOT(ISBLANK('Wand Mapping'!$C16)), "CO") -> CO | K16: =IF(B16=FALSE, IF(C16=FALSE, IF(D16=FALSE, IF(E16=FALSE, "RAND", E16), D16), C16), B16) -> RAND | L16: =IF(K16="RAND", OFFSET(F16, 0, MOD(RAND(), 3)), K16) -> NE | M16: TR | N16: =_xlfn.CONCAT(A16, "-", M16, ".BAM") -> wand_ai_140-TR.BAM
A17: ='Wand Mapping'!K17 -> wand_ai_150 | B17: =IF(NOT(ISBLANK('Wand Mapping'!$J17)), "WM") -> FALSE | C17: =IF(NOT(ISBLANK('Wand Mapping'!$D17)), "DI") -> FALSE | D17: =IF(NOT(ISBLANK('Wand Mapping'!$I17)), "IL") -> FALSE | E17: =IF(NOT(ISBLANK('Wand Mapping'!$G17)), "EN") -> FALSE | F17: =IF(NOT(ISBLANK('Wand Mapping'!$H17)), "NE") -> NE | G17: =IF(NOT(ISBLANK('Wand Mapping'!$B17)), "AB") -> AB | H17: =IF(NOT(ISBLANK('Wand Mapping'!$F17)), "EV") -> EV | I17: =IF(NOT(ISBLANK('Wand Mapping'!$E17)), "TR") -> TR | J17: =IF(NOT(ISBLANK('Wand Mapping'!$C17)), "CO") -> CO | K17: =IF(B17=FALSE, IF(C17=FALSE, IF(D17=FALSE, IF(E17=FALSE, "RAND", E17), D17), C17), B17) -> RAND | L17: =IF(K17="RAND", OFFSET(F17, 0, MOD(RAND(), 3)), K17) -> NE | M17: CO | N17: =_xlfn.CONCAT(A17, "-", M17, ".BAM") -> wand_ai_150-CO.BAM
A18: ='Wand Mapping'!K18 -> wand_ai_160 | B18: =IF(NOT(ISBLANK('Wand Mapping'!$J18)), "WM") -> FALSE | C18: =IF(NOT(ISBLANK('Wand Mapping'!$D18)), "DI") -> FALSE | D18: =IF(NOT(ISBLANK('Wand Mapping'!$I18)), "IL") -> FALSE | E18: =IF(NOT(ISBLANK('Wand Mapping'!$G18)), "EN") -> FALSE | F18: =IF(NOT(ISBLANK('Wand Mapping'!$H18)), "NE") -> NE | G18: =IF(NOT(ISBLANK('Wand Mapping'!$B18)), "AB") -> FALSE | H18: =IF(NOT(ISBLANK('Wand Mapping'!$F18)), "EV") -> EV | I18: =IF(NOT(ISBLANK('Wand Mapping'!$E18)), "TR") -> TR | J18: =IF(NOT(ISBLANK('Wand Mapping'!$C18)), "CO") -> CO | K18: =IF(B18=FALSE, IF(C18=FALSE, IF(D18=FALSE, IF(E18=FALSE, "RAND", E18), D18), C18), B18) -> RAND | L18: =IF(K18="RAND", OFFSET(F18, 0, MOD(RAND(), 3)), K18) -> NE | M18: EV | N18: =_xlfn.CONCAT(A18, "-", M18, ".BAM") -> wand_ai_160-EV.BAM
A19: ='Wand Mapping'!K19 -> wand_ai_170 | B19: =IF(NOT(ISBLANK('Wand Mapping'!$J19)), "WM") -> FALSE | C19: =IF(NOT(ISBLANK('Wand Mapping'!$D19)), "DI") -> DI | D19: =IF(NOT(ISBLANK('Wand Mapping'!$I19)), "IL") -> IL | E19: =IF(NOT(ISBLANK('Wand Mapping'!$G19)), "EN") -> EN | F19: =IF(NOT(ISBLANK('Wand Mapping'!$H19)), "NE") -> FALSE | G19: =IF(NOT(ISBLANK('Wand Mapping'!$B19)), "AB") -> AB | H19: =IF(NOT(ISBLANK('Wand Mapping'!$F19)), "EV") -> EV | I19: =IF(NOT(ISBLANK('Wand Mapping'!$E19)), "TR") -> TR | J19: =IF(NOT(ISBLANK('Wand Mapping'!$C19)), "CO") -> CO | K19: =IF(B19=FALSE, IF(C19=FALSE, IF(D19=FALSE, IF(E19=FALSE, "RAND", E19), D19), C19), B19) -> DI | L19: =IF(K19="RAND", OFFSET(F19, 0, MOD(RAND(), 3)), K19) -> DI | M19: =IF(L19=FALSE, ,L19) -> DI | N19: =_xlfn.CONCAT(A19, "-", M19, ".BAM") -> wand_ai_170-DI.BAM
A20: ='Wand Mapping'!K20 -> wand_ai_180 | B20: =IF(NOT(ISBLANK('Wand Mapping'!$J20)), "WM") -> FALSE | C20: =IF(NOT(ISBLANK('Wand Mapping'!$D20)), "DI") -> FALSE | D20: =IF(NOT(ISBLANK('Wand Mapping'!$I20)), "IL") -> IL | E20: =IF(NOT(ISBLANK('Wand Mapping'!$G20)), "EN") -> FALSE | F20: =IF(NOT(ISBLANK('Wand Mapping'!$H20)), "NE") -> FALSE | G20: =IF(NOT(ISBLANK('Wand Mapping'!$B20)), "AB") -> FALSE | H20: =IF(NOT(ISBLANK('Wand Mapping'!$F20)), "EV") -> EV | I20: =IF(NOT(ISBLANK('Wand Mapping'!$E20)), "TR") -> TR | J20: =IF(NOT(ISBLANK('Wand Mapping'!$C20)), "CO") -> CO | K20: =IF(B20=FALSE, IF(C20=FALSE, IF(D20=FALSE, IF(E20=FALSE, "RAND", E20), D20), C20), B20) -> IL | L20: =IF(K20="RAND", OFFSET(F20, 0, MOD(RAND(), 3)), K20) -> IL | M20: =IF(L20=FALSE, ,L20) -> IL | N20: =_xlfn.CONCAT(A20, "-", M20, ".BAM") -> wand_ai_180-IL.BAM
A21: ='Wand Mapping'!K21 -> wand_ai_190 | B21: =IF(NOT(ISBLANK('Wand Mapping'!$J21)), "WM") -> FALSE | C21: =IF(NOT(ISBLANK('Wand Mapping'!$D21)), "DI") -> FALSE | D21: =IF(NOT(ISBLANK('Wand Mapping'!$I21)), "IL") -> FALSE | E21: =IF(NOT(ISBLANK('Wand Mapping'!$G21)), "EN") -> FALSE | F21: =IF(NOT(ISBLANK('Wand Mapping'!$H21)), "NE") -> NE | G21: =IF(NOT(ISBLANK('Wand Mapping'!$B21)), "AB") -> FALSE | H21: =IF(NOT(ISBLANK('Wand Mapping'!$F21)), "EV") -> EV | I21: =IF(NOT(ISBLANK('Wand Mapping'!$E21)), "TR") -> TR | J21: =IF(NOT(ISBLANK('Wand Mapping'!$C21)), "CO") -> CO | K21: =IF(B21=FALSE, IF(C21=FALSE, IF(D21=FALSE, IF(E21=FALSE, "RAND", E21), D21), C21), B21) -> RAND | L21: =IF(K21="RAND", OFFSET(F21, 0, MOD(RAND(), 3)), K21) -> NE | M21: =IF(L21=FALSE, ,L21) -> NE | N21: =_xlfn.CONCAT(A21, "-", M21, ".BAM") -> wand_ai_190-NE.BAM
A22: ='Wand Mapping'!K22 -> wand_ai_200 | B22: =IF(NOT(ISBLANK('Wand Mapping'!$J22)), "WM") -> FALSE | C22: =IF(NOT(ISBLANK('Wand Mapping'!$D22)), "DI") -> FALSE | D22: =IF(NOT(ISBLANK('Wand Mapping'!$I22)), "IL") -> FALSE | E22: =IF(NOT(ISBLANK('Wand Mapping'!$G22)), "EN") -> FALSE | F22: =IF(NOT(ISBLANK('Wand Mapping'!$H22)), "NE") -> NE | G22: =IF(NOT(ISBLANK('Wand Mapping'!$B22)), "AB") -> FALSE | H22: =IF(NOT(ISBLANK('Wand Mapping'!$F22)), "EV") -> EV | I22: =IF(NOT(ISBLANK('Wand Mapping'!$E22)), "TR") -> TR | J22: =IF(NOT(ISBLANK('Wand Mapping'!$C22)), "CO") -> CO | K22: =IF(B22=FALSE, IF(C22=FALSE, IF(D22=FALSE, IF(E22=FALSE, "RAND", E22), D22), C22), B22) -> RAND | L22: =IF(K22="RAND", OFFSET(F22, 0, MOD(RAND(), 3)), K22) -> NE | M22: =IF(L22=FALSE, ,L22) -> NE | N22: =_xlfn.CONCAT(A22, "-", M22, ".BAM") -> wand_ai_200-NE.BAM
A23: ='Wand Mapping'!K23 -> wand_ai_210 | B23: =IF(NOT(ISBLANK('Wand Mapping'!$J23)), "WM") -> FALSE | C23: =IF(NOT(ISBLANK('Wand Mapping'!$D23)), "DI") -> DI | D23: =IF(NOT(ISBLANK('Wand Mapping'!$I23)), "IL") -> FALSE | E23: =IF(NOT(ISBLANK('Wand Mapping'!$G23)), "EN") -> FALSE | F23: =IF(NOT(ISBLANK('Wand Mapping'!$H23)), "NE") -> NE | G23: =IF(NOT(ISBLANK('Wand Mapping'!$B23)), "AB") -> AB | H23: =IF(NOT(ISBLANK('Wand Mapping'!$F23)), "EV") -> EV | I23: =IF(NOT(ISBLANK('Wand Mapping'!$E23)), "TR") -> TR | J23: =IF(NOT(ISBLANK('Wand Mapping'!$C23)), "CO") -> CO | K23: =IF(B23=FALSE, IF(C23=FALSE, IF(D23=FALSE, IF(E23=FALSE, "RAND", E23), D23), C23), B23) -> DI | L23: =IF(K23="RAND", OFFSET(F23, 0, MOD(RAND(), 3)), K23) -> DI | M23: =IF(L23=FALSE, ,L23) -> DI | N23: =_xlfn.CONCAT(A23, "-", M23, ".BAM") -> wand_ai_210-DI.BAM
A24: ='Wand Mapping'!K24 -> wand_ai_220 | B24: =IF(NOT(ISBLANK('Wand Mapping'!$J24)), "WM") -> FALSE | C24: =IF(NOT(ISBLANK('Wand Mapping'!$D24)), "DI") -> FALSE | D24: =IF(NOT(ISBLANK('Wand Mapping'!$I24)), "IL") -> FALSE | E24: =IF(NOT(ISBLANK('Wand Mapping'!$G24)), "EN") -> EN | F24: =IF(NOT(ISBLANK('Wand Mapping'!$H24)), "NE") -> NE | G24: =IF(NOT(ISBLANK('Wand Mapping'!$B24)), "AB") -> AB | H24: =IF(NOT(ISBLANK('Wand Mapping'!$F24)), "EV") -> FALSE | I24: =IF(NOT(ISBLANK('Wand Mapping'!$E24)), "TR") -> TR | J24: =IF(NOT(ISBLANK('Wand Mapping'!$C24)), "CO") -> CO | K24: =IF(B24=FALSE, IF(C24=FALSE, IF(D24=FALSE, IF(E24=FALSE, "RAND", E24), D24), C24), B24) -> EN | L24: =IF(K24="RAND", OFFSET(F24, 0, MOD(RAND(), 3)), K24) -> EN | M24: =IF(L24=FALSE, ,L24) -> EN | N24: =_xlfn.CONCAT(A24, "-", M24, ".BAM") -> wand_ai_220-EN.BAM
A25: ='Wand Mapping'!K25 -> wand_ai_230 | B25: =IF(NOT(ISBLANK('Wand Mapping'!$J25)), "WM") -> FALSE | C25: =IF(NOT(ISBLANK('Wand Mapping'!$D25)), "DI") -> FALSE | D25: =IF(NOT(ISBLANK('Wand Mapping'!$I25)), "IL") -> FALSE | E25: =IF(NOT(ISBLANK('Wand Mapping'!$G25)), "EN") -> FALSE | F25: =IF(NOT(ISBLANK('Wand Mapping'!$H25)), "NE") -> FALSE | G25: =IF(NOT(ISBLANK('Wand Mapping'!$B25)), "AB") -> FALSE | H25: =IF(NOT(ISBLANK('Wand Mapping'!$F25)), "EV") -> EV | I25: =IF(NOT(ISBLANK('Wand Mapping'!$E25)), "TR") -> TR | J25: =IF(NOT(ISBLANK('Wand Mapping'!$C25)), "CO") -> CO | K25: =IF(B25=FALSE, IF(C25=FALSE, IF(D25=FALSE, IF(E25=FALSE, "RAND", E25), D25), C25), B25) -> RAND | L25: =IF(K25="RAND", OFFSET(F25, 0, MOD(RAND(), 3)), K25) -> FALSE | M25: EV | N25: =_xlfn.CONCAT(A25, "-", M25, ".BAM") -> wand_ai_230-EV.BAM
A26: ='Wand Mapping'!K26 -> wand_ai_240 | B26: =IF(NOT(ISBLANK('Wand Mapping'!$J26)), "WM") -> FALSE | C26: =IF(NOT(ISBLANK('Wand Mapping'!$D26)), "DI") -> DI | D26: =IF(NOT(ISBLANK('Wand Mapping'!$I26)), "IL") -> FALSE | E26: =IF(NOT(ISBLANK('Wand Mapping'!$G26)), "EN") -> FALSE | F26: =IF(NOT(ISBLANK('Wand Mapping'!$H26)), "NE") -> NE | G26: =IF(NOT(ISBLANK('Wand Mapping'!$B26)), "AB") -> AB | H26: =IF(NOT(ISBLANK('Wand Mapping'!$F26)), "EV") -> EV | I26: =IF(NOT(ISBLANK('Wand Mapping'!$E26)), "TR") -> TR | J26: =IF(NOT(ISBLANK('Wand Mapping'!$C26)), "CO") -> CO | K26: =IF(B26=FALSE, IF(C26=FALSE, IF(D26=FALSE, IF(E26=FALSE, "RAND", E26), D26), C26), B26) -> DI | L26: =IF(K26="RAND", OFFSET(F26, 0, MOD(RAND(), 3)), K26) -> DI | M26: =IF(L26=FALSE, ,L26) -> DI | N26: =_xlfn.CONCAT(A26, "-", M26, ".BAM") -> wand_ai_240-DI.BAM
A27: ='Wand Mapping'!K27 -> wand_ai_250 | B27: =IF(NOT(ISBLANK('Wand Mapping'!$J27)), "WM") -> FALSE | C27: =IF(NOT(ISBLANK('Wand Mapping'!$D27)), "DI") -> FALSE | D27: =IF(NOT(ISBLANK('Wand Mapping'!$I27)), "IL") -> FALSE | E27: =IF(NOT(ISBLANK('Wand Mapping'!$G27)), "EN") -> EN | F27: =IF(NOT(ISBLANK('Wand Mapping'!$H27)), "NE") -> FALSE | G27: =IF(NOT(ISBLANK('Wand Mapping'!$B27)), "AB") -> AB | H27: =IF(NOT(ISBLANK('Wand Mapping'!$F27)), "EV") -> EV | I27: =IF(NOT(ISBLANK('Wand Mapping'!$E27)), "TR") -> TR | J27: =IF(NOT(ISBLANK('Wand Mapping'!$C27)), "CO") -> CO | K27: =IF(B27=FALSE, IF(C27=FALSE, IF(D27=FALSE, IF(E27=FALSE, "RAND", E27), D27), C27), B27) -> EN | L27: =IF(K27="RAND", OFFSET(F27, 0, MOD(RAND(), 3)), K27) -> EN | M27: =IF(L27=FALSE, ,L27) -> EN | N27: =_xlfn.CONCAT(A27, "-", M27, ".BAM") -> wand_ai_250-EN.BAM
A28: ='Wand Mapping'!K28 -> wand_ai_260 | B28: =IF(NOT(ISBLANK('Wand Mapping'!$J28)), "WM") -> FALSE | C28: =IF(NOT(ISBLANK('Wand Mapping'!$D28)), "DI") -> FALSE | D28: =IF(NOT(ISBLANK('Wand Mapping'!$I28)), "IL") -> FALSE | E28: =IF(NOT(ISBLANK('Wand Mapping'!$G28)), "EN") -> FALSE | F28: =IF(NOT(ISBLANK('Wand Mapping'!$H28)), "NE") -> FALSE | G28: =IF(NOT(ISBLANK('Wand Mapping'!$B28)), "AB") -> AB | H28: =IF(NOT(ISBLANK('Wand Mapping'!$F28)), "EV") -> FALSE | I28: =IF(NOT(ISBLANK('Wand Mapping'!$E28)), "TR") -> TR | J28: =IF(NOT(ISBLANK('Wand Mapping'!$C28)), "CO") -> CO | K28: =IF(B28=FALSE, IF(C28=FALSE, IF(D28=FALSE, IF(E28=FALSE, "RAND", E28), D28), C28), B28) -> RAND | L28: =IF(K28="RAND", OFFSET(F28, 0, MOD(RAND(), 3)), K28) -> FALSE | M28: TR | N28: =_xlfn.CONCAT(A28, "-", M28, ".BAM") -> wand_ai_260-TR.BAM
A29: ='Wand Mapping'!K29 -> wand_ai_270 | B29: =IF(NOT(ISBLANK('Wand Mapping'!$J29)), "WM") -> FALSE | C29: =IF(NOT(ISBLANK('Wand Mapping'!$D29)), "DI") -> FALSE | D29: =IF(NOT(ISBLANK('Wand Mapping'!$I29)), "IL") -> FALSE | E29: =IF(NOT(ISBLANK('Wand Mapping'!$G29)), "EN") -> EN | F29: =IF(NOT(ISBLANK('Wand Mapping'!$H29)), "NE") -> NE | G29: =IF(NOT(ISBLANK('Wand Mapping'!$B29)), "AB") -> AB | H29: =IF(NOT(ISBLANK('Wand Mapping'!$F29)), "EV") -> FALSE | I29: =IF(NOT(ISBLANK('Wand Mapping'!$E29)), "TR") -> TR | J29: =IF(NOT(ISBLANK('Wand Mapping'!$C29)), "CO") -> CO | K29: =IF(B29=FALSE, IF(C29=FALSE, IF(D29=FALSE, IF(E29=FALSE, "RAND", E29), D29), C29), B29) -> EN | L29: =IF(K29="RAND", OFFSET(F29, 0, MOD(RAND(), 3)), K29) -> EN | M29: =IF(L29=FALSE, ,L29) -> EN | N29: =_xlfn.CONCAT(A29, "-", M29, ".BAM") -> wand_ai_270-EN.BAM
A30: ='Wand Mapping'!K30 -> wand_ai_280 | B30: =IF(NOT(ISBLANK('Wand Mapping'!$J30)), "WM") -> FALSE | C30: =IF(NOT(ISBLANK('Wand Mapping'!$D30)), "DI") -> FALSE | D30: =IF(NOT(ISBLANK('Wand Mapping'!$I30)), "IL") -> FALSE | E30: =IF(NOT(ISBLANK('Wand Mapping'!$G30)), "EN") -> FALSE | F30: =IF(NOT(ISBLANK('Wand Mapping'!$H30)), "NE") -> NE | G30: =IF(NOT(ISBLANK('Wand Mapping'!$B30)), "AB") -> FALSE | H30: =IF(NOT(ISBLANK('Wand Mapping'!$F30)), "EV") -> EV | I30: =IF(NOT(ISBLANK('Wand Mapping'!$E30)), "TR") -> TR | J30: =IF(NOT(ISBLANK('Wand Mapping'!$C30)), "CO") -> CO | K30: =IF(B30=FALSE, IF(C30=FALSE, IF(D30=FALSE, IF(E30=FALSE, "RAND", E30), D30), C30), B30) -> RAND | L30: =IF(K30="RAND", OFFSET(F30, 0, MOD(RAND(), 3)), K30) -> NE | M30: =IF(L30=FALSE, ,L30) -> NE | N30: =_xlfn.CONCAT(A30, "-", M30, ".BAM") -> wand_ai_280-NE.BAM
A31: ='Wand Mapping'!K31 -> wand_ai_290 | B31: =IF(NOT(ISBLANK('Wand Mapping'!$J31)), "WM") -> FALSE | C31: =IF(NOT(ISBLANK('Wand Mapping'!$D31)), "DI") -> DI | D31: =IF(NOT(ISBLANK('Wand Mapping'!$I31)), "IL") -> FALSE | E31: =IF(NOT(ISBLANK('Wand Mapping'!$G31)), "EN") -> EN | F31: =IF(NOT(ISBLANK('Wand Mapping'!$H31)), "NE") -> NE | G31: =IF(NOT(ISBLANK('Wand Mapping'!$B31)), "AB") -> FALSE | H31: =IF(NOT(ISBLANK('Wand Mapping'!$F31)), "EV") -> EV | I31: =IF(NOT(ISBLANK('Wand Mapping'!$E31)), "TR") -> TR | J31: =IF(NOT(ISBLANK('Wand Mapping'!$C31)), "CO") -> CO | K31: =IF(B31=FALSE, IF(C31=FALSE, IF(D31=FALSE, IF(E31=FALSE, "RAND", E31), D31), C31), B31) -> DI | L31: =IF(K31="RAND", OFFSET(F31, 0, MOD(RAND(), 3)), K31) -> DI | M31: =IF(L31=FALSE, ,L31) -> DI | N31: =_xlfn.CONCAT(A31, "-", M31, ".BAM") -> wand_ai_290-DI.BAM
A32: ='Wand Mapping'!K32 -> wand_ai_300 | B32: =IF(NOT(ISBLANK('Wand Mapping'!$J32)), "WM") -> FALSE | C32: =IF(NOT(ISBLANK('Wand Mapping'!$D32)), "DI") -> FALSE | D32: =IF(NOT(ISBLANK('Wand Mapping'!$I32)), "IL") -> IL | E32: =IF(NOT(ISBLANK('Wand Mapping'!$G32)), "EN") -> FALSE | F32: =IF(NOT(ISBLANK('Wand Mapping'!$H32)), "NE") -> NE | G32: =IF(NOT(ISBLANK('Wand Mapping'!$B32)), "AB") -> AB | H32: =IF(NOT(ISBLANK('Wand Mapping'!$F32)), "EV") -> EV | I32: =IF(NOT(ISBLANK('Wand Mapping'!$E32)), "TR") -> TR | J32: =IF(NOT(ISBLANK('Wand Mapping'!$C32)), "CO") -> CO | K32: =IF(B32=FALSE, IF(C32=FALSE, IF(D32=FALSE, IF(E32=FALSE, "RAND", E32), D32), C32), B32) -> IL | L32: =IF(K32="RAND", OFFSET(F32, 0, MOD(RAND(), 3)), K32) -> IL | M32: =IF(L32=FALSE, ,L32) -> IL | N32: =_xlfn.CONCAT(A32, "-", M32, ".BAM") -> wand_ai_300-IL.BAM
A33: ='Wand Mapping'!K33 -> wand_ai_310 | B33: =IF(NOT(ISBLANK('Wand Mapping'!$J33)), "WM") -> FALSE | C33: =IF(NOT(ISBLANK('Wand Mapping'!$D33)), "DI") -> FALSE | D33: =IF(NOT(ISBLANK('Wand Mapping'!$I33)), "IL") -> FALSE | E33: =IF(NOT(ISBLANK('Wand Mapping'!$G33)), "EN") -> FALSE | F33: =IF(NOT(ISBLANK('Wand Mapping'!$H33)), "NE") -> NE | G33: =IF(NOT(ISBLANK('Wand Mapping'!$B33)), "AB") -> AB | H33: =IF(NOT(ISBLANK('Wand Mapping'!$F33)), "EV") -> FALSE | I33: =IF(NOT(ISBLANK('Wand Mapping'!$E33)), "TR") -> TR | J33: =IF(NOT(ISBLANK('Wand Mapping'!$C33)), "CO") -> CO | K33: =IF(B33=FALSE, IF(C33=FALSE, IF(D33=FALSE, IF(E33=FALSE, "RAND", E33), D33), C33), B33) -> RAND | L33: =IF(K33="RAND", OFFSET(F33, 0, MOD(RAND(), 3)), K33) -> NE | M33: =IF(L33=FALSE, ,L33) -> NE | N33: =_xlfn.CONCAT(A33, "-", M33, ".BAM") -> wand_ai_310-NE.BAM
A34: ='Wand Mapping'!K34 -> wand_ai_320 | B34: =IF(NOT(ISBLANK('Wand Mapping'!$J34)), "WM") -> FALSE | C34: =IF(NOT(ISBLANK('Wand Mapping'!$D34)), "DI") -> FALSE | D34: =IF(NOT(ISBLANK('Wand Mapping'!$I34)), "IL") -> FALSE | E34: =IF(NOT(ISBLANK('Wand Mapping'!$G34)), "EN") -> FALSE | F34: =IF(NOT(ISBLANK('Wand Mapping'!$H34)), "NE") -> NE | G34: =IF(NOT(ISBLANK('Wand Mapping'!$B34)), "AB") -> AB | H34: =IF(NOT(ISBLANK('Wand Mapping'!$F34)), "EV") -> EV | I34: =IF(NOT(ISBLANK('Wand Mapping'!$E34)), "TR") -> TR | J34: =IF(NOT(ISBLANK('Wand Mapping'!$C34)), "CO") -> CO | K34: =IF(B34=FALSE, IF(C34=FALSE, IF(D34=FALSE, IF(E34=FALSE, "RAND", E34), D34), C34), B34) -> RAND | L34: =IF(K34="RAND", OFFSET(F34, 0, MOD(RAND(), 3)), K34) -> NE | M34: =IF(L34=FALSE, ,L34) -> NE | N34: =_xlfn.CONCAT(A34, "-", M34, ".BAM") -> wand_ai_320-NE.BAM
A35: ='Wand Mapping'!K35 -> wand_ai_330 | B35: =IF(NOT(ISBLANK('Wand Mapping'!$J35)), "WM") -> FALSE | C35: =IF(NOT(ISBLANK('Wand Mapping'!$D35)), "DI") -> FALSE | D35: =IF(NOT(ISBLANK('Wand Mapping'!$I35)), "IL") -> FALSE | E35: =IF(NOT(ISBLANK('Wand Mapping'!$G35)), "EN") -> FALSE | F35: =IF(NOT(ISBLANK('Wand Mapping'!$H35)), "NE") -> NE | G35: =IF(NOT(ISBLANK('Wand Mapping'!$B35)), "AB") -> AB | H35: =IF(NOT(ISBLANK('Wand Mapping'!$F35)), "EV") -> EV | I35: =IF(NOT(ISBLANK('Wand Mapping'!$E35)), "TR") -> TR | J35: =IF(NOT(ISBLANK('Wand Mapping'!$C35)), "CO") -> CO | K35: =IF(B35=FALSE, IF(C35=FALSE, IF(D35=FALSE, IF(E35=FALSE, "RAND", E35), D35), C35), B35) -> RAND | L35: =IF(K35="RAND", OFFSET(F35, 0, MOD(RAND(), 3)), K35) -> NE | M35: =IF(L35=FALSE, ,L35) -> NE | N35: =_xlfn.CONCAT(A35, "-", M35, ".BAM") -> wand_ai_330-NE.BAM
A36: ='Wand Mapping'!K36 -> wand_ai_340 | B36: =IF(NOT(ISBLANK('Wand Mapping'!$J36)), "WM") -> WM | C36: =IF(NOT(ISBLANK('Wand Mapping'!$D36)), "DI") -> FALSE | D36: =IF(NOT(ISBLANK('Wand Mapping'!$I36)), "IL") -> FALSE | E36: =IF(NOT(ISBLANK('Wand Mapping'!$G36)), "EN") -> FALSE | F36: =IF(NOT(ISBLANK('Wand Mapping'!$H36)), "NE") -> NE | G36: =IF(NOT(ISBLANK('Wand Mapping'!$B36)), "AB") -> AB | H36: =IF(NOT(ISBLANK('Wand Mapping'!$F36)), "EV") -> EV | I36: =IF(NOT(ISBLANK('Wand Mapping'!$E36)), "TR") -> TR | J36: =IF(NOT(ISBLANK('Wand Mapping'!$C36)), "CO") -> CO | K36: =IF(B36=FALSE, IF(C36=FALSE, IF(D36=FALSE, IF(E36=FALSE, "RAND", E36), D36), C36), B36) -> WM | L36: =IF(K36="RAND", OFFSET(F36, 0, MOD(RAND(), 3)), K36) -> WM | M36: =IF(L36=FALSE, ,L36) -> WM | N36: =_xlfn.CONCAT(A36, "-", M36, ".BAM") -> wand_ai_340-WM.BAM
A37: ='Wand Mapping'!K37 -> wand_ai_350 | B37: =IF(NOT(ISBLANK('Wand Mapping'!$J37)), "WM") -> FALSE | C37: =IF(NOT(ISBLANK('Wand Mapping'!$D37)), "DI") -> FALSE | D37: =IF(NOT(ISBLANK('Wand Mapping'!$I37)), "IL") -> FALSE | E37: =IF(NOT(ISBLANK('Wand Mapping'!$G37)), "EN") -> FALSE | F37: =IF(NOT(ISBLANK('Wand Mapping'!$H37)), "NE") -> NE | G37: =IF(NOT(ISBLANK('Wand Mapping'!$B37)), "AB") -> AB | H37: =IF(NOT(ISBLANK('Wand Mapping'!$F37)), "EV") -> EV | I37: =IF(NOT(ISBLANK('Wand Mapping'!$E37)), "TR") -> TR | J37: =IF(NOT(ISBLANK('Wand Mapping'!$C37)), "CO") -> CO | K37: =IF(B37=FALSE, IF(C37=FALSE, IF(D37=FALSE, IF(E37=FALSE, "RAND", E37), D37), C37), B37) -> RAND | L37: =IF(K37="RAND", OFFSET(F37, 0, MOD(RAND(), 3)), K37) -> NE | M37: =IF(L37=FALSE, ,L37) -> NE | N37: =_xlfn.CONCAT(A37, "-", M37, ".BAM") -> wand_ai_350-NE.BAM
A38: ='Wand Mapping'!K38 -> wand_ai_360 | B38: =IF(NOT(ISBLANK('Wand Mapping'!$J38)), "WM") -> FALSE | C38: =IF(NOT(ISBLANK('Wand Mapping'!$D38)), "DI") -> FALSE | D38: =IF(NOT(ISBLANK('Wand Mapping'!$I38)), "IL") -> FALSE | E38: =IF(NOT(ISBLANK('Wand Mapping'!$G38)), "EN") -> FALSE | F38: =IF(NOT(ISBLANK('Wand Mapping'!$H38)), "NE") -> FALSE | G38: =IF(NOT(ISBLANK('Wand Mapping'!$B38)), "AB") -> AB | H38: =IF(NOT(ISBLANK('Wand Mapping'!$F38)), "EV") -> EV | I38: =IF(NOT(ISBLANK('Wand Mapping'!$E38)), "TR") -> TR | J38: =IF(NOT(ISBLANK('Wand Mapping'!$C38)), "CO") -> CO | K38: =IF(B38=FALSE, IF(C38=FALSE, IF(D38=FALSE, IF(E38=FALSE, "RAND", E38), D38), C38), B38) -> RAND | L38: =IF(K38="RAND", OFFSET(F38, 0, MOD(RAND(), 3)), K38) -> FALSE | M38: CO | N38: =_xlfn.CONCAT(A38, "-", M38, ".BAM") -> wand_ai_360-CO.BAM
A39: ='Wand Mapping'!K39 -> wand_ai_370 | B39: =IF(NOT(ISBLANK('Wand Mapping'!$J39)), "WM") -> FALSE | C39: =IF(NOT(ISBLANK('Wand Mapping'!$D39)), "DI") -> FALSE | D39: =IF(NOT(ISBLANK('Wand Mapping'!$I39)), "IL") -> FALSE | E39: =IF(NOT(ISBLANK('Wand Mapping'!$G39)), "EN") -> FALSE | F39: =IF(NOT(ISBLANK('Wand Mapping'!$H39)), "NE") -> NE | G39: =IF(NOT(ISBLANK('Wand Mapping'!$B39)), "AB") -> AB | H39: =IF(NOT(ISBLANK('Wand Mapping'!$F39)), "EV") -> EV | I39: =IF(NOT(ISBLANK('Wand Mapping'!$E39)), "TR") -> TR | J39: =IF(NOT(ISBLANK('Wand Mapping'!$C39)), "CO") -> CO | K39: =IF(B39=FALSE, IF(C39=FALSE, IF(D39=FALSE, IF(E39=FALSE, "RAND", E39), D39), C39), B39) -> RAND | L39: =IF(K39="RAND", OFFSET(F39, 0, MOD(RAND(), 3)), K39) -> NE | M39: =IF(L39=FALSE, ,L39) -> NE | N39: =_xlfn.CONCAT(A39, "-", M39, ".BAM") -> wand_ai_370-NE.BAM
A40: ='Wand Mapping'!K40 -> wand_ai_380 | B40: =IF(NOT(ISBLANK('Wand Mapping'!$J40)), "WM") -> FALSE | C40: =IF(NOT(ISBLANK('Wand Mapping'!$D40)), "DI") -> FALSE | D40: =IF(NOT(ISBLANK('Wand Mapping'!$I40)), "IL") -> FALSE | E40: =IF(NOT(ISBLANK('Wand Mapping'!$G40)), "EN") -> FALSE | F40: =IF(NOT(ISBLANK('Wand Mapping'!$H40)), "NE") -> NE | G40: =IF(NOT(ISBLANK('Wand Mapping'!$B40)), "AB") -> AB | H40: =IF(NOT(ISBLANK('Wand Mapping'!$F40)), "EV") -> EV | I40: =IF(NOT(ISBLANK('Wand Mapping'!$E40)), "TR") -> TR | J40: =IF(NOT(ISBLANK('Wand Mapping'!$C40)), "CO") -> CO | K40: =IF(B40=FALSE, IF(C40=FALSE, IF(D40=FALSE, IF(E40=FALSE, "RAND", E40), D40), C40), B40) -> RAND | L40: =IF(K40="RAND", OFFSET(F40, 0, MOD(RAND(), 3)), K40) -> NE | M40: =IF(L40=FALSE, ,L40) -> NE | N40: =_xlfn.CONCAT(A40, "-", M40, ".BAM") -> wand_ai_380-NE.BAM
...

Sheet Spell Data
A1: Name | B1: Final School
A2: Abi-Dalzim's Horrid Wilting | B2: Necromancy
A3: Absolute Guard | B3: Abjuration
A4: Absolute Immunity | B4: Abjuration
A5: Absord Spell | B5: Abjuration
A6: Acid Storm | B6: Invocation
A7: Aerial Servant | B7: Conjuration
A8: Agannazar's Scorcher | B8: Invocation
A9: Aid | B9: Necromancy
A10: Alicorn Lance | B10: Invocation
A11: Animal Growth | B11: Transmutation
A12: Animal Rage | B12: Enchantment
... A530: Zone of Sweet Air | B530: Abjuration

Sheet Spells By School
A1: Abjuration | B1: Conjuration | C1: Divination | D1: Transmutation | E1: Invocation | F1: Enchantment | G1: Necromancy | H1: Illusion | I1: Wild Magic
A2: Absolute Guard | B2: Aerial Servant | C2: Beast Sense | D2: Animal Growth | E2: Acid Storm | F2: Animal Rage | G2: =IFERROR(__xludf.DUMMYFUNCTION("query( {'Spell Data'!$A$2:$B$530}, ""Select Col1 where Col2='""&G$1&""'"" )"),"Abi-Dalzim's Horrid Wilting") -> Abi-Dalzim's Horrid Wilting | H2: Backstab Sequencer | I2: Chaos Shield*
A3: Absolute Immunity | B3: Animal Summoning 1 | C3: Clairvoyance | D3: Attain Perfection | E3: Agannazar's Scorcher | F3: Chaos | G3: =IFERROR(__xludf.DUMMYFUNCTION("""COMPUTED_VALUE"""),"Aid") -> Aid | H3: Blindness | I3: Disruptive Surge
A4: Absord Spell | B4: Animal Summoning 2 | C4: Contact Other Plane | D4: Barkskin | E4: Alicorn Lance | F4: Chaotic Commands | G4: =IFERROR(__xludf.DUMMYFUNCTION("""COMPUTED_VALUE"""),"Animate Dead") -> Animate Dead | H4: Blur | I4: Improved Chaos Shield*
A5: Antiharm Shell | B5: Animal Summoning 3 | C5: Detect Evil | D5: Barrage | E5: Aura of Flaming Death | F5: Charm Person | G5: =IFERROR(__xludf.DUMMYFUNCTION("""COMPUTED_VALUE"""),"Beltyn's Burning Blood") -> Beltyn's Burning Blood | H5: Camouflage | I5: Nahal's Reckless Dweomer*
A6: Antimagic Shell | B6: Armor | C6: Detect Illusion | D6: Beast Claw | E6: Ball Lightning | F6: Charm Person or Mammal | G6: =IFERROR(__xludf.DUMMYFUNCTION("""COMPUTED_VALUE"""),"Cause Critical Wounds") -> Cause Critical Wounds | H6: Clone Other
A7: Armor of Faith | B7: Bless | C7: Detect Invisibility | D7: Blood Rage | E7: Bigby's Clenched Fist | F7: Command | G7: =IFERROR(__xludf.DUMMYFUNCTION("""COMPUTED_VALUE"""),"Cause Light Wounds") -> Cause Light Wounds | H7: Deafness
A8: Bounce Spell | B8: Cacofiend | C8: Detect Magic | D8: Burning Hands | E8: Bigby's Crushing Hand | F8: Confusion | G8: =IFERROR(__xludf.DUMMYFUNCTION("""COMPUTED_VALUE"""),"Cause Medium Wounds") -> Cause Medium Wounds | H8: Demi-Shadow Monsters
A9: Breach | B9: Call Water Weirds | C9: Executioner's Eyes | D9: Call Lightning | E9: Black Blade of Disaster | F9: Contagious Fear | G9: =IFERROR(__xludf.DUMMYFUNCTION("""COMPUTED_VALUE"""),"Cause Moderate Wounds") -> Cause Moderate Wounds | H9: Displacement
A10: Cause Disease | B10: Call Woodland Beings | C10: Extend Vision | D10: Cat's Grace | E10: Blade Barrier | F10: Contingency Curse | G10: =IFERROR(__xludf.DUMMYFUNCTION("""COMPUTED_VALUE"""),"Cause Serious Wounds") -> Cause Serious Wounds | H10: Globe of Invisibility
A11: Cure Disease | B11: Carrion Summons | C11: Far Cast | D11: Champion's Strength | E11: Bolt of Glory | F11: Control Slime | G11: =IFERROR(__xludf.DUMMYFUNCTION("""COMPUTED_VALUE"""),"Chill Touch") -> Chill Touch | H11: Improved Invisibility
A12: Damage Turning | B12: Chant | C12: Farsight | D12: Cloud of Pestilance | E12: Chain Contingency | F12: Critical Spell | G12: =IFERROR(__xludf.DUMMYFUNCTION("""COMPUTED_VALUE"""),"Circle of Bones") -> Circle of Bones | H12: Invisibility
A13: Dispel Magic | B13: Cloak of Fear | C13: Find Traps | D13: Color Spray | E13: Chain Lightning | F13: Defensive Harmony | G13: =IFERROR(__xludf.DUMMYFUNCTION("""COMPUTED_VALUE"""),"Contagion") -> Contagion | H13: Invisibility 10' Radius
A14: Entropy Shield | B14: Colossal Growth | C14: Hunter's Mark | D14: Critical Boon | E14: Chromatic Orb | F14: Dire Charm | G14: Contingent Resurrection | H14: Major Mirror Image
A15: Exaltation | B15: Comet | C15: Identify | D15: Dimension Door | E15: Cloudburst | F15: Disarm | G15: Control Undead | H15: Mass Invisibility
A16: Expose to the Elements | B16: Commando Conjuration | C16: Infravision | D16: Disintigrate | E16: Cone of Cold | F16: Domination | G16: Culling Thought | H16: Mirror Image
A17: Forcecage | B17: Conjure Air Elemental | C17: Invisibility Purge | D17: Dolorous Decay | E17: Contingency | F17: Eclectic Recall | G17: Cure Critical Wounds | H17: Mislead
A18: Free Action | B18: Conjure Animals | C18: Know Alignment | D18: Doom | E18: Death Fog | F18: Emotion: Courage | G18: Cure Light Wounds | H18: Nature's Beauty
A19: Freedom | B19: Conjure Earth Elemental | C19: Legend Lore | D19: Drown | E19: Decastave | F19: Emotion: Hope | G19: Cure Medium Wounds | H19: Perfect Invisibility
A20: Globe of Invulnerability | B20: Conjure Fire Elemental | C20: Oracle | D20: Earthquake | E20: Delayed Blast Fireball | F20: Emotion: Hopelessness | G20: Cure Moderate Wounds | H20: Phantasmal Dragon
A21: Glyph of Spell Storing | B21: Copy Spell | C21: True Sight | D21: Enhance Attribute | E21: Dragon's Breath | F21: Enchanted Weapon | G21: Cure Serious Wounds | H21: Phantasmal Killer
A22: Glyph of Warding | B22: Create Pit | C22: True Strike | D22: Enoll Eva's Duplication | E22: Draw Upon Holy Might | F22: Enslave | G22: Darts of Bone | H22: Pixie Dust
A23: Guardian Magic | B23: Creeping Doom | D23: Entangle | E23: Energy Blades | F23: Extraordinary Luck | G23: Death Spell | H23: Project Image
A24: Heightening | B24: Curse | D24: Ether Gate | E24: False Dawn | F24: Feeblemind | G24: Death Trigger | H24: Reflected Image
A25: Impervious Sanctity of Mind | B25: Dimensional Chest | D25: Expeditious Retreat | E25: Fiery Link | F25: Friends | G25: Death Ward | H25: Shades
A26: Imprisonment | B26: Elemental Summoning | D26: Fire Curse | E26: Fire Shield (Blue) | F26: Greater Command | G26: Destruction | H26: Shadow Door
A27: Improved Alacrity | B27: Elysium's Tears | D27: Fire Earth Transformation | E27: Fire Shield (Red) | F27: Greater Malison | G27: Energy Drain | H27: Shadow Monsters
A28: Improved Mantle | B28: Empower Familiar | D28: Fire Elemental Transformation | E28: Fire Storm | F28: Greater Nightmare | G28: False Life | H28: Simulacrum
A29: Khelben's Warding Whip | B29: Ethereal Retribution | D29: Flesh to Stone | E29: Fireball | F29: Hex | G29: Favor of Illmater | H29: Spook
A30: Mantle | B30: Familiar Spell | D30: Fly | E30: Flame Blade | F30: Hold Animal | G30: Favored of the Spirits | H30: Warrior Simulacrum
A31: Mind Blank | B31: Find Familiar | D31: Freeze Inanimates | E31: Freezing Wave | F31: Hold Monster | G31: Finger of Death | H31: Wraith Form
A32: Minor Globe of Invulnerability | B32: Fire Seeds | D32: Ghostform | E32: Gedlee's Electric Barrier | F32: Hold Person | G32: Ghoul Touch
A33: Minor Spell Deflection | B33: Flame Arrow | D33: Ghostwalk | E33: Globe of Blades | F33: Intoxicate | G33: Ghoulish Feast
A34: Minor Spell Turning | B34: Forest's Blessing | D34: Giant Insect | E34: Goodberry | F34: Luck | G34: Greater Restoration
A35: Negative Plane Protection | B35: Gate | D35: Greater Steel Wind Strike | E35: Great Shout | F35: Magic Stone | G35: Harm
A36: Non-Detection | B36: Ghost Armor | D36: Haste | E36: Greater Living Lightning | F36: Mass Charm | G36: Heal
A37: Pierce Magic | B37: Glitterdust | D37: Healing Curse | E37: Heavenly Inferno | F37: Mass Domination | G37: Hold Undead
A38: Pierce Shield | B38: Grease | D38: Implosion | E38: Holy Power | F38: Mental Agility | G38: Holy Smite
A39: Power Word: Push | B39: Greater Elemental Summoning | D39: Improved Haste | E39: Ice Storm | F39: Mental Domination | G39: Horror
A40: Protection from Acid | B40: Greater Shield of Lathander | D40: Inertia | E40: Icelance | F40: Mind Fog | G40: Larloch's Minor Drain
...

Sheet Wand Recipes
A1: Custom | B1: Wand Code | C1: Spell Level | D1: CasterLevel | E1: Name | F1: Spell File | G1: Source | H1: SubSource | I1: Detail | J1: School | K1: Result RESREF
A2: FALSE | B2: OHDWAND1 | C2: 2 | D2: 3 | E2: Wand of Glitterdust | F2: SPWI224 | G2: Base Game | H2: BG2EE
A3: FALSE | B3: OHNWAND1 | E3: Wand of Whips | F3: Magic Missile, Web, Warding whip? | G3: Base Game | H3: BG2EE
A4: FALSE | B4: RODS01 | C4: 6 | D4: 12 | E4: Rod of Absorbtion | F4: SPWI618 | G4: Base Game | H4: BG2EE
A5: FALSE | B5: RODS03 | C5: 7 | D5: 14 | E5: Rod of Resurrection | F5: SPPR712 | G5: Base Game | H5: BG2EE
A6: FALSE | B6: RODS06 | C6: 7 | D6: 14 | E6: Rod of Reversal | F6: SPWI704 | G6: Base Game | H6: BG2EE
A7: FALSE | B7: WAND19 | C7: 2 | D7: 3 | E7: Wand of Cursing | F7: SPWI223 / / | G7: Base Game | H7: BG2EE
A8: FALSE | B8: BDWAND01 | E8: Wand of Water Elemental Summoning | F8: WIZARD_CONJURE_WATER_ELEMENTAL | G8: Base Game | H8: Core
A9: FALSE | B9: WAND02 | C9: 2 | D9: 3 | E9: Wand of Fear | F9: SPWI205 | G9: Base Game | H9: Core
A10: FALSE | B10: WAND03 | C10: 1 | D10: 1 | E10: Wand of Magic Missiles | F10: SPWI112 | G10: Base Game | H10: Core
A11: FALSE | B11: WAND04 | C11: 3 | D11: 5 | E11: Wand of Paralyzation | F11: SPWI306 | G11: Base Game | H11: Core
A12: FALSE | B12: WAND05 | C12: 3 | D12: 5 | E12: Wand of Fire | F12: SPWI304 (Fireball) / SPWI217 (Agannazar's Scorcher) | G12: Base Game | H12: Core
A13: FALSE | B13: WAND06 | C13: 4 | D13: 7 | E13: Wand of Frost | F13: SPWI217 (Agannazar's Scorcher) / SPWI404 (Ice Storm) / SPWI503 (Cone of Cold) | G13: Base Game | H13: Core
A14: FALSE | B14: WAND07 | C14: 3 | D14: 5 | E14: Wand of Lightning | F14: SPWI308 | G14: Base Game | H14: Core
A15: FALSE | B15: WAND08 | C15: 1 | D15: 1 | E15: Wand of Sleep | F15: SPWI116 | G15: Base Game | H15: Core
A16: FALSE | B16: WAND09 | C16: 4 | D16: 7 | E16: Wand of Polymorphing | F16: SPWI415 | G16: Base Game | H16: Core
A17: FALSE | B17: WAND10 | C17: 4 | D17: 7 | E17: Wand of Monster Summoning | F17: SPWI407 | G17: Base Game | H17: Core
A18: FALSE | B18: WAND11 | C18: 5 | D18: 9 | E18: Wand of the Heavens | F18: SPPR503 | G18: Base Game | H18: Core
A19: FALSE | B19: WAND12 | E19: Wand of Wonder | F19: various. TBD in recipes | G19: Base Game | H19: Core
A20: FALSE | B20: WAND13 | C20: 5 | D20: 9 | E20: Wand of Cloudkill | F20: SPWI502 | G20: Base Game | H20: Core
A21: FALSE | B21: WAND15 | E21: Wand of the Apprenti | F21: various. TBD in recipes | G21: Base Game | H21: Core
A22: FALSE | B22: WAND18 | C22: 6 | D22: 12 | E22: Wand of Spell Striking | F22: SPWI608 / Pierce Magic / Breach | G22: Base Game | H22: Core
A23: FALSE | B23: WANDARM | C23: 3 | D23: 5 | E23: Wand of Armory | F23: SPWI317 (ghost armor) / SPWI114 (shield) | G23: Base Game | H23: IWDEE
A24: FALSE | B24: WANDCOR | C24: 7 | D24: 14 | E24: Wand of Corrosion | F24: SPWI724 (Acid Storm) / SPWI614 (DeathFog) | G24: Base Game | H24: IWDEE
A25: FALSE | B25: WANDFRE | C25: 4 | D25: 7 | E25: Wand of Freezing Death | F25: SPWI204 (Snilloc) / SPWI327 (Icelance) / SPWI404 (Ice Storm) | G25: Base Game | H25: IWDEE
A26: FALSE | B26: WANDMIS | C26: 1 | D26: 5 | E26: Pemby's Wand of Many Missiles | F26: SPWI112 | G26: Base Game | H26: IWDEE | I26: Magic Missile level 5
A27: FALSE | B27: WANDTRP | C27: 2 | D27: 3 | E27: Wand of Trap Detection | F27: SPPR205 (Find traps) | G27: Base Game | H27: IWDEE
A28: TRUE | B28: BZ-1_ | C28: 1 | D28: 1 | E28: Grease | F28: SPWI101 | G28: Caster Crafting | H28: Core
A29: TRUE | B29: BZ-10 | C29: 1 | D29: 1 | E29: Armor | F29: SPWI102 | G29: Caster Crafting | H29: Core
A30: TRUE | B30: BZ-11 | C30: 1 | D30: 1 | E30: Burning Hands | F30: SPWI103 | G30: Caster Crafting | H30: Core
A31: TRUE | B31: BZ-12 | C31: 1 | D31: 1 | E31: Charm Person | F31: SPWI104 | G31: Caster Crafting | H31: Core
A32: TRUE | B32: BZ-13 | C32: 1 | D32: 1 | E32: Color Spray | F32: SPWI105 | G32: Caster Crafting | H32: Core
A33: TRUE | B33: BZ-14 | C33: 1 | D33: 1 | E33: Blindness | F33: SPWI106 | G33: Caster Crafting | H33: Core
A34: TRUE | B34: BZ-15 | C34: 1 | D34: 1 | E34: Friends | F34: SPWI107 | G34: Caster Crafting | H34: Core
A35: TRUE | B35: BZ-16 | C35: 1 | D35: 1 | E35: Protection from Petrification | F35: SPWI108 | G35: Caster Crafting | H35: Core
A36: TRUE | B36: BZ-17 | C36: 1 | D36: 1 | E36: Identify | F36: SPWI110 | G36: Caster Crafting | H36: Core
A37: TRUE | B37: BZ-18 | C37: 1 | D37: 1 | E37: Infravision | F37: SPWI111 | G37: Caster Crafting | H37: Core
A38: TRUE | B38: BZ-19 | C38: 1 | D38: 1 | E38: Magic Missile | F38: SPWI112 | G38: Caster Crafting | H38: Core
... A346: TRUE | B346: BZ-A5 | C346: 10 | D346: 18 | E346: Comet | F346: SPWI925 | G346: Caster Crafting | H346: Core
A347: TRUE | B347: BZ-A6 | C347: Q | D347: 18 | E347: Energy Blades | F347: SPPR721 | G347: Caster Crafting | H347: Core
...

Sheet Missing Wand Definitions
A1: Name | B1: Wand Code | C1: Spell Level | D1: CasterLevel | E1: Result RESREF | F1: Spell File | G1: Source | H1: SubSource | I1: Detail | J1: Abjuration | K1: Conjuration | L1: Divination | M1: Transmutation | N1: Invocation | O1: Enchantment | P1: Necromancy | Q1: Illusion | R1: Wild Magic | S1: Spell School | T1: Image Suffix | U1: Match Row | V1: Image Name | W1: BAM | X1: BAM Override | Y1: Note | Z1: BAM Final | AA1: Usability: Mage | AB1: Usability: Cleric | AC1: Usability: Druid | AD1: Usability: Bard | AE1: Usability: Paladin | AF1: Usability: Ranger | AG1: Usability: Shaman | AH1: Usability: Good | AI1: Usability: ... Neutral | AJ1: Usability: Evil | AK1: Usability: Lawful | AL1: Usability: Neutral ... | AM1: Usability: Chaotic | AN1: Usability Any Class | AO1: Duration: Opcode | AP1: Duration: Offset | AQ1: Magnitude: Opcode | AR1: Magnitude: Offset | AS1: Magnitude 2: Opcode | AT1: Magnitude 2: Offset | AU1: Kit Restrictions | AV1: Title STRREF BG(2)EE | AW1: Description STRREF BG(2)EE | AX1: Title STRREF IWD | AY1: Description STRREF IWD | AZ1: Title STRREF Olvyn | BA1: Description STRREF Olvyn | BB1: Title STRREF Spell Rev. | BC1: Description STRREF Spell Rev. | BD1: Expected Title STTREF | BE1: Expected Description STTREF | BF1: Title STRREF Match | BG1: Description STRREF Match
A2: Grease | B2: BZ-1_ | C2: 1 | D2: 1 | E2: =_xlfn.CONCAT(B2, RIGHT(_xlfn.CONCAT("0", D2), 2)) -> BZ-1_01 | F2: SPWI101 | G2: Caster Crafting | H2: Core | J2: =MATCH($A2, 'Spells By School'!A:A, 0) -> #N/A | K2: =MATCH($A2, 'Spells By School'!B:B, 0) -> 38 | L2: =MATCH($A2, 'Spells By School'!C:C, 0) -> #N/A | M2: =MATCH($A2, 'Spells By School'!D:D, 0) -> #N/A | N2: =MATCH($A2, 'Spells By School'!E:E, 0) -> #N/A | O2: =MATCH($A2, 'Spells By School'!F:F, 0) -> #N/A | P2: =MATCH($A2, 'Spells By School'!G:G, 0) -> #N/A | Q2: =MATCH($A2, 'Spells By School'!H:H, 0) -> #N/A | R2: =MATCH($A2, 'Spells By School'!I:I, 0) -> #N/A | S2: =IF(ISNA($J2), IF(ISNA($K2), IF(ISNA($L2), IF(ISNA($M2), IF(ISNA($N2), IF(ISNA($O2), IF(ISNA($P2), IF(ISNA($Q2), IF(ISNA($R2), "###error###", R$1),Q$1),P$1),O$1),N$1),M$1),L$1),K$1),J$1) -> Conjuration | T2: =IF(ISNA($J2), IF(ISNA($K2), IF(ISNA($L2), IF(ISNA($M2), IF(ISNA($N2), IF(ISNA($O2), IF(ISNA($P2), IF(ISNA($Q2), IF(ISNA($R2), "###error###", "WM"),"IL"),"NE"),"EN"),"EV"),"TR"),"DI"),"CO"),"AB") -> CO | U2: =IF(ISNA($J2), IF(ISNA($K2), IF(ISNA($L2), IF(ISNA($M2), IF(ISNA($N2), IF(ISNA($O2), IF(ISNA($P2), IF(ISNA($Q2), IF(ISNA($R2), "###error###", MATCH(A2, 'Wand Mapping'!J:J,0)),MATCH(A2, 'Wand Mapping'!I:I,0)),MATCH(A2, 'Wand Mapping'!H:H,0)),MATCH(A2, 'Wand Mapping'!G:G,0)),MATCH(A2, 'Wand Mapping'!F:F,0)),MATCH(A2, 'Wand Mapping'!E:E,0)),MATCH(A2, 'Wand Mapping'!D:D,0)),MATCH(A2, 'Wand Mapping'!C:C,0)),MATCH(A2, 'Wand Mapping'!B:B,0)) -> 97 | V2: =INDEX('Wand Mapping'!K:K, U2) -> wand_ai_950 | W2: =_xlfn.CONCAT(V2, "_", T2) -> wand_ai_950_CO | Z2: =IF(ISBLANK(X2), W2, X2) -> wand_ai_950_CO | AA2: TRUE | AD2: TRUE | AH2: TRUE | AI2: TRUE | AJ2: TRUE | AK2: TRUE | AL2: TRUE | AM2: TRUE | AN2: TRUE | AV2: 61000 | AW2: 61001 | AX2: 71000 | AY2: 71001 | BB2: 91000 | BC2: 91001 | BD2: 1000 | BE2: =IF(BD2="", "", BD2+1) -> 1001 | BF2: =AND( OR(ISBLANK(AV2), AND(MOD(AV2, 10000) = BD2, QUOTIENT(AV2, 10000) = 6)), OR(ISBLANK(AX2), AND(MOD(AX2, 10000) = BD2, QUOTIENT(AX2, 10000) = 7)), OR(ISBLANK(AZ2), AND(MOD(AZ2, 10000) = BD2, QUOTIENT(AZ2, 10000) = 8)), OR(ISBLANK(BB2), AND(MOD(BB2, 10000) = BD2, QUOTIENT(BB2, 10000) = 9)) ) -> TRUE | BG2: =AND( OR(ISBLANK(AW2), AND(MOD(AW2, 10000) = BE2, QUOTIENT(AW2, 10000) = 6)), OR(ISBLANK(AY2), AND(MOD(AY2, 10000) = BE2, QUOTIENT(AY2, 10000) = 7)), OR(ISBLANK(BA2), AND(MOD(BA2, 10000) = BE2, QUOTIENT(BA2, 10000) = 8)), OR(ISBLANK(BC2), AND(MOD(BC2, 10000) = BE2, QUOTIENT(BC2, 10000) = 9)) ) -> TRUE
A3: Armor | B3: BZ-10 | C3: 1 | D3: 1 | E3: =_xlfn.CONCAT(B3, RIGHT(_xlfn.CONCAT("0", D3), 2)) -> BZ-1001 | F3: SPWI102 | G3: Caster Crafting | H3: Core | J3: =MATCH($A3, 'Spells By School'!A:A, 0) -> #N/A | K3: =MATCH($A3, 'Spells By School'!B:B, 0) -> 6 | L3: =MATCH($A3, 'Spells By School'!C:C, 0) -> #N/A | M3: =MATCH($A3, 'Spells By School'!D:D, 0) -> #N/A | N3: =MATCH($A3, 'Spells By School'!E:E, 0) -> #N/A | O3: =MATCH($A3, 'Spells By School'!F:F, 0) -> #N/A | P3: =MATCH($A3, 'Spells By School'!G:G, 0) -> #N/A | Q3: =MATCH($A3, 'Spells By School'!H:H, 0) -> #N/A | R3: =MATCH($A3, 'Spells By School'!I:I, 0) -> #N/A | S3: =IF(ISNA($J3), IF(ISNA($K3), IF(ISNA($L3), IF(ISNA($M3), IF(ISNA($N3), IF(ISNA($O3), IF(ISNA($P3), IF(ISNA($Q3), IF(ISNA($R3), "###error###", R$1),Q$1),P$1),O$1),N$1),M$1),L$1),K$1),J$1) -> Conjuration | T3: =IF(ISNA($J3), IF(ISNA($K3), IF(ISNA($L3), IF(ISNA($M3), IF(ISNA($N3), IF(ISNA($O3), IF(ISNA($P3), IF(ISNA($Q3), IF(ISNA($R3), "###error###", "WM"),"IL"),"NE"),"EN"),"EV"),"TR"),"DI"),"CO"),"AB") -> CO | U3: =IF(ISNA($J3), IF(ISNA($K3), IF(ISNA($L3), IF(ISNA($M3), IF(ISNA($N3), IF(ISNA($O3), IF(ISNA($P3), IF(ISNA($Q3), IF(ISNA($R3), "###error###", MATCH(A3, 'Wand Mapping'!J:J,0)),MATCH(A3, 'Wand Mapping'!I:I,0)),MATCH(A3, 'Wand Mapping'!H:H,0)),MATCH(A3, 'Wand Mapping'!G:G,0)),MATCH(A3, 'Wand Mapping'!F:F,0)),MATCH(A3, 'Wand Mapping'!E:E,0)),MATCH(A3, 'Wand Mapping'!D:D,0)),MATCH(A3, 'Wand Mapping'!C:C,0)),MATCH(A3, 'Wand Mapping'!B:B,0)) -> 94 | V3: =INDEX('Wand Mapping'!K:K, U3) -> wand_ai_920 | W3: =_xlfn.CONCAT(V3, "_", T3) -> wand_ai_920_CO | Z3: =IF(ISBLANK(X3), W3, X3) -> wand_ai_920_CO | AA3: TRUE | AD3: TRUE | AH3: TRUE | AI3: TRUE | AJ3: TRUE | AK3: TRUE | AL3: TRUE | AM3: TRUE | AN3: TRUE | AV3: 61002 | AW3: 61003 | BB3: 91002 | BC3: 91003 | BD3: 1002 | BE3: =IF(BD3="", "", BD3+1) -> 1003 | BF3: =AND( OR(ISBLANK(AV3), AND(MOD(AV3, 10000) = BD3, QUOTIENT(AV3, 10000) = 6)), OR(ISBLANK(AX3), AND(MOD(AX3, 10000) = BD3, QUOTIENT(AX3, 10000) = 7)), OR(ISBLANK(AZ3), AND(MOD(AZ3, 10000) = BD3, QUOTIENT(AZ3, 10000) = 8)), OR(ISBLANK(BB3), AND(MOD(BB3, 10000) = BD3, QUOTIENT(BB3, 10000) = 9)) ) -> TRUE | BG3: =AND( OR(ISBLANK(AW3), AND(MOD(AW3, 10000) = BE3, QUOTIENT(AW3, 10000) = 6)), OR(ISBLANK(AY3), AND(MOD(AY3, 10000) = BE3, QUOTIENT(AY3, 10000) = 7)), OR(ISBLANK(BA3), AND(MOD(BA3, 10000) = BE3, QUOTIENT(BA3, 10000) = 8)), OR(ISBLANK(BC3), AND(MOD(BC3, 10000) = BE3, QUOTIENT(BC3, 10000) = 9)) ) -> TRUE
A4: Burning Hands | B4: BZ-11 | C4: 1 | D4: 1 | E4: =_xlfn.CONCAT(B4, RIGHT(_xlfn.CONCAT("0", D4), 2)) -> BZ-1101 | F4: SPWI103 | G4: Caster Crafting | H4: Core | J4: =MATCH($A4, 'Spells By School'!A:A, 0) -> #N/A | K4: =MATCH($A4, 'Spells By School'!B:B, 0) -> #N/A | L4: =MATCH($A4, 'Spells By School'!C:C, 0) -> #N/A | M4: =MATCH($A4, 'Spells By School'!D:D, 0) -> 8 | N4: =MATCH($A4, 'Spells By School'!E:E, 0) -> #N/A | O4: =MATCH($A4, 'Spells By School'!F:F, 0) -> #N/A | P4: =MATCH($A4, 'Spells By School'!G:G, 0) -> #N/A | Q4: =MATCH($A4, 'Spells By School'!H:H, 0) -> #N/A | R4: =MATCH($A4, 'Spells By School'!I:I, 0) -> #N/A | S4: =IF(ISNA($J4), IF(ISNA($K4), IF(ISNA($L4), IF(ISNA($M4), IF(ISNA($N4), IF(ISNA($O4), IF(ISNA($P4), IF(ISNA($Q4), IF(ISNA($R4), "###error###", R$1),Q$1),P$1),O$1),N$1),M$1),L$1),K$1),J$1) -> Transmutation | T4: =IF(ISNA($J4), IF(ISNA($K4), IF(ISNA($L4), IF(ISNA($M4), IF(ISNA($N4), IF(ISNA($O4), IF(ISNA($P4), IF(ISNA($Q4), IF(ISNA($R4), "###error###", "WM"),"IL"),"NE"),"EN"),"EV"),"TR"),"DI"),"CO"),"AB") -> TR | U4: =IF(ISNA($J4), IF(ISNA($K4), IF(ISNA($L4), IF(ISNA($M4), IF(ISNA($N4), IF(ISNA($O4), IF(ISNA($P4), IF(ISNA($Q4), IF(ISNA($R4), "###error###", MATCH(A4, 'Wand Mapping'!J:J,0)),MATCH(A4, 'Wand Mapping'!I:I,0)),MATCH(A4, 'Wand Mapping'!H:H,0)),MATCH(A4, 'Wand Mapping'!G:G,0)),MATCH(A4, 'Wand Mapping'!F:F,0)),MATCH(A4, 'Wand Mapping'!E:E,0)),MATCH(A4, 'Wand Mapping'!D:D,0)),MATCH(A4, 'Wand Mapping'!C:C,0)),MATCH(A4, 'Wand Mapping'!B:B,0)) -> 40 | V4: =INDEX('Wand Mapping'!K:K, U4) -> wand_ai_380 | W4: =_xlfn.CONCAT(V4, "_", T4) -> wand_ai_380_TR | Z4: =IF(ISBLANK(X4), W4, X4) -> wand_ai_380_TR | AA4: TRUE | AD4: TRUE | AH4: TRUE | AI4: TRUE | AJ4: TRUE | AK4: TRUE | AL4: TRUE | AM4: TRUE | AV4: 61004 | AW4: 61005 | AX4: 71004 | AY4: 71005 | BB4: 91004 | BC4: 91005 | BD4: 1004 | BE4: =IF(BD4="", "", BD4+1) -> 1005 | BF4: =AND( OR(ISBLANK(AV4), AND(MOD(AV4, 10000) = BD4, QUOTIENT(AV4, 10000) = 6)), OR(ISBLANK(AX4), AND(MOD(AX4, 10000) = BD4, QUOTIENT(AX4, 10000) = 7)), OR(ISBLANK(AZ4), AND(MOD(AZ4, 10000) = BD4, QUOTIENT(AZ4, 10000) = 8)), OR(ISBLANK(BB4), AND(MOD(BB4, 10000) = BD4, QUOTIENT(BB4, 10000) = 9)) ) -> TRUE | BG4: =AND( OR(ISBLANK(AW4), AND(MOD(AW4, 10000) = BE4, QUOTIENT(AW4, 10000) = 6)), OR(ISBLANK(AY4), AND(MOD(AY4, 10000) = BE4, QUOTIENT(AY4, 10000) = 7)), OR(ISBLANK(BA4), AND(MOD(BA4, 10000) = BE4, QUOTIENT(BA4, 10000) = 8)), OR(ISBLANK(BC4), AND(MOD(BC4, 10000) = BE4, QUOTIENT(BC4, 10000) = 9)) ) -> TRUE
